Workbook

Sheet GF1_ABS
A1: =GF1_MES!A1 -> BRIDGE AT CHAINAGE (PADLI GUJARESHWAR)
A2: ABSTRACT OF COST
A3: S.No. | B3: Particulars. | C3: Quantity | E3: Rate | F3: Unit | G3: Amount
A4: 1 | B4: 1 Earthwork in excavation for foundation of B-1 structure complete with all lift, dewatering, 1.1.4 shoring and shuttering etc. including refilling of trenches in 250 mm layer, ramming, watering and disposal of surplus soll within a lead of 1000 meters, as per drawing and technical Earth In excavation for foundation of specification. [MORTH Specification: Clause 304]. in ordinary soll [MORTH Specification clause 301] BY MECHANICAL MEANS Depth upto 3m | C4: =GF1_MES!K10 -> 618.579 | D4: Cum | E4: 57 | F4: P Cum | G4: =C4*E4 -> 35259.003
A5: 2 | B5: Earthwork In excavation for foundation of B-1 structure complete with all lift, dewatering, 1.3.2 shoring and shuttering etc. including refilling of trenches in 250 mm layer, ramming, watering and disposal of surplus soil within a lead of 1000 meters, as per drawing and technical Earth in excavation for foundation of specification. [MORTH Specification Clause 304].In Ordinary/Soft rock (not requiring blasting) [MORTH Specification: Clause 3011 BY MECHANICAL MEANS | C5: =GF1_MES!K17 -> 572.205 | D5: Cum | E5: 83 | F5: P Cum | G5: =C5*E5 -> 47493.015
A6: 3 | B6: Earthwork in excavation for foundation of B-1 structure complete with all lift, dewatering. 1.4.2 shoring and shuttering etc. including refilling of trenches in 250 mm layer, ramming, watering and disposal of surplus soil within a lead of 1000 meters, as per drawing and technical Earth in excavation for foundation of specification. [MORTH Specification: Clause 304]. In Hard Rock [MORTH Specification : Clause 301, 302, 303]. Blasting Prohibited | C6: =GF1_MES!K24 -> 1088.31 | D6: Cum | E6: 670 | F6: P Cum | G6: =C6*E6 -> 729167.7
A7: 4 | B7: Structural cement concrete (Design Mix) in open foundations, with form work, at level. Cement concrete for plain/reinforced concrete in open foundations as per drawing and technical specification. [MORTH Specification: Section 1700 & 1500). With 20mm nominal size aggregate P.C.C. M-20 grade | C7: =GF1_MES!K31 -> 114.441 | D7: Cum | E7: 4017 | F7: P Cum | G7: =C7*E7 -> 459709.5
A8: 5 | B8: Structural cement concrete (Design Mix) B-2 in open foundations, with form work, at 6.6.6 any level. Cement plain/reinforced concrete for concrete in open foundations as per drawing and technical specification. [MORTH Specification : Section 1700 & 1500]. With 20mm nominal size aggregate R.C.C. M-25 grade | C8: =GF1_MES!K40 -> 961.60825 | D8: Cum | E8: 4341 | F8: P Cum | G8: =C8*E8 -> 4174341.4
A9: 6 | B9: Providing and laying steel reinforcement at any level in foundation complete as per 13.1 drawing and technical specification. [MORTH Specification: Section 1600]. HYSD bar reinforcement | C9: =GF1_MES!K45 -> 64.547 | D9: T | E9: 88567 | F9: P tonne | G9: =C9*E9 -> 5716734.1
A10: 7 | B10: Structural cement concrete (Design Mix) in open foundations, with form work, at level. Cement concrete for plain/reinforced concrete in open foundations as per drawing and technical specification. [MORTH Specification: Section 1700 & 1500). With 20mm nominal size aggregate P.C.C. M-15 grade | C10: =GF1_MES!K52 -> 272.8 | D10: Cum | E10: 3038 | F10: P Cum | G10: =C10*E10 -> 828766.4
A11: 8 | B11: Structural cement concrete for plain concrete/ reinforced concrete for substructure at any level, complete as per [MORTH Specification: Section 1500 & 1700]. drawing and technical specification. Design mix concrete PCC M-25 Upto 5 mtr. Height | C11: =GF1_MES!K63 -> 372.0885 | D11: cum | E11: 4319 | F11: P Cum | G11: =C11*E11 -> 1607050.2
A12: 9 | B12: Steel reinforcement in substructure HYSD reinforcement | C12: =GF1_MES!K68 -> 57.159 | D12: T | E12: 88737 | F12: P tonne | G12: =C12*E12 -> 5072118.2
A13: 10 | B13: Providing A.C. pipe Weep holes 150mm B-3 dia in Masonry/plain Concrete/Reinforced 13 Concrete abutment, wing wall/return wall complete as per drawing and technical specification. [MORTH Specification : Clause 2205]. | C13: =GF1_MES!K79 -> 408.5 | D13: R mtr | E13: 114 | F13: P RM | G13: =C13*E13 -> 46569
A14: 11 | B14: Providing and and filling in foundation Btrenches, and back filling behind abutments, wing walls, return wall etc., and below pipe bed in layers not exceeding 150mm thick including watering and compacting (IRC-78) | C14: =GF1_MES!K87 -> 10.113 | D14: cum | E14: 745 | F14: P Cum | G14: =C14*E14 -> 7534.185
A15: 12 | B15: Filter medium behind abutment, wing wall and return wall, complete as per drawing and technical specification. (Same as R7.20.3) [MORTH Specification: Clause 2504]. | C15: =GF1_MES!K91 -> 419.13 | D15: cum | E15: 560 | F15: P Cum | G15: =C15*E15 -> 234712.8
A16: 13 | B16: Structural RCC/PSC upto a height of 5 mtr. for reinforced concrete in superstructure complete including steel formwork, scaffolding etc. As per drawing and technical specification.Design mix concrete. [MORTH Specification : 1500 & 1700].RCC M-30 grade Solid slab superstructure at any level in superstructure complete as per drawing and technical Specification. [MORTH Specification: Section 1600] | C16: =GF1_MES!K96 -> 297.091 | D16: cum | E16: 6307 | F16: P Cum | G16: =C16*E16 -> 1873752.9
A17: 14 | B17: Steel reinforcement in Superstructure HYSD reinforcement | C17: =GF1_MES!K98 -> 27.064 | D17: T | E17: 89654 | F17: P tonne | G17: =C17*E17 -> 2426395.9
A18: 15 | B18: Reinforced cement concrete wearing coat B-4 M-30 grade at any level including formwork and reinforcement complete as per drawing and technical Specification. MORTH Specification: Clause 2204, 1500 & 1700]. | C18: =GF1_MES!K101 -> 43.5625 | D18: Cum | E18: 7720 | F18: P Cum | G18: =C18*E18 -> 336302.5
A19: 16 | B19: Providing and Laying PCC M-15 grade B-4 leveling course below approach slab 15 complete as per drawing and technical specifications. [MORTH specification: 2700] | C19: =GF1_MES!K103 -> 14.22 | D19: cum | E19: 2471 | F19: P Cum | G19: =C19*E19 -> 35137.62
A20: 17 | B20: Reinforced cement concrete M-30 grade B-4 approach slab including reinforcement 16 and formwork complete as per drawing and technical specifications. [MoRTH specification: 1500, 1600, 1700, 2704] | C20: =GF1_MES!K107 -> 21.33 | D20: cum | E20: 7073 | F20: P Cum | G20: =C20*E20 -> 150867.09
A21: 18 | B21: Providing, laying and fixing of Filler Joint Providing and fixing 2mm thick Corrugated Copper Plate in expansion joint complete as per drawing and technical specifications in MORTH specification: clause 2605. | C21: =GF1_MES!K109 -> 31.875 | D21: Sqm | E21: 3673 | F21: P Sqm | G21: =C21*E21 -> 117076.88
E22: Total | F22: Rs. | G22: =SUM(G4:G15) -> 18959456

Sheet GF1_MES
A1: BRIDGE AT CHAINAGE (PADLI GUJARESHWAR)
A2: DETAILS OF MEASUREMENTS
A3: S.N. | B3: Particulars | C3: Nos. | E3: Length | G3: Breadth | I3: Height | K3: Qty. | L3: Units
A4: 1 | B4: Earthwork in excavation for foundation of structure complete with all lift, dewatering, 1.1.4 shoring and shuttering etc. including refilling of trenches in 250 mm layer, ramming, watering and disposal of surplus soll within a lead of 1000 meters, as per drawing and technical Earth In excavation for foundation of specification. [MORTH Specification: Clause 304]. in ordinary soll [MORTH Specification clause 301] BY MECHANICAL MEANS Depth upto 3m
B5: Abutment A1 | C5: 1 | D5: x | E5: 8.5 | F5: x | G5: 8.8 | H5: x | I5: 1.5 | J5: = | K5: =IF(C5,C5*E5*G5*I5,"") -> 112.2 | L5: Cum
B6: Piers | C6: 1 | D6: x | E6: 5.9 | F6: x | G6: 13.1 | H6: x | I6: 1.65 | J6: = | K6: =IF(C6,C6*E6*G6*I6,"") -> 127.5285 | L6: Cum
C7: 1 | D7: x | E7: 5.9 | F7: x | G7: 13.1 | H7: x | I7: 1.65 | J7: = | K7: =IF(C7,C7*E7*G7*I7,"") -> 127.5285 | L7: Cum
C8: 1 | D8: x | E8: 5.9 | F8: x | G8: 13.1 | H8: x | I8: 1.8 | J8: = | K8: =IF(C8,C8*E8*G8*I8,"") -> 139.122 | L8: Cum
B9: Abutment A2 | C9: 1 | D9: x | E9: 8.5 | F9: x | G9: 8.8 | H9: x | I9: 1.5 | J9: = | K9: =IF(C9,C9*E9*G9*I9,"") -> 112.2 | L9: Cum
G10: Total Qty. | K10: =SUM(K5:K9) -> 618.579 | L10: Cum
A11: 2 | B11: Earthwork In excavation for foundation of B-1 structure complete with all lift, dewatering, 1.3.2 shoring and shuttering etc. including refilling of trenches in 250 mm layer, ramming, watering and disposal of surplus soil within a lead of 1000 meters, as per drawing and technical Earth in excavation for foundation of specification. [MORTH Specification Clause 304].In Ordinary/Soft rock (not requiring blasting) [MORTH Specification: Clause 3011 BY MECHANICAL MEANS
B12: Abutment A1 | C12: 1 | D12: x | E12: 8.5 | F12: x | G12: 8.8 | H12: x | I12: 1.5 | J12: = | K12: =IF(C12,C12*E12*G12*I12,"") -> 112.2 | L12: Cum
B13: Piers | C13: 1 | D13: x | E13: 5.9 | F13: x | G13: 13.1 | H13: x | I13: 1.5 | J13: = | K13: =IF(C13,C13*E13*G13*I13,"") -> 115.935 | L13: Cum
C14: 1 | D14: x | E14: 5.9 | F14: x | G14: 13.1 | H14: x | I14: 1.5 | J14: = | K14: =IF(C14,C14*E14*G14*I14,"") -> 115.935 | L14: Cum
C15: 1 | D15: x | E15: 5.9 | F15: x | G15: 13.1 | H15: x | I15: 1.5 | J15: = | K15: =IF(C15,C15*E15*G15*I15,"") -> 115.935 | L15: Cum
B16: Abutment A2 | C16: 1 | D16: x | E16: 8.5 | F16: x | G16: 8.8 | H16: x | I16: 1.5 | J16: = | K16: =IF(C16,C16*E16*G16*I16,"") -> 112.2 | L16: Cum
G17: Total Qty. | K17: =SUM(K12:K16) -> 572.205 | L17: Cum
A18: 3 | B18: Earthwork in excavation for foundation of B-1 structure complete with all lift, dewatering. 1.4.2 shoring and shuttering etc. including refilling of trenches in 250 mm layer, ramming, watering and disposal of surplus soil within a lead of 1000 meters, as per drawing and technical Earth in excavation for foundation of specification. [MORTH Specification: Clause 304]. In Hard Rock [MORTH Specification : Clause 301, 302, 303]. Blasting Prohibited
B19: Abutment A1 | C19: 1 | D19: x | E19: 8.5 | F19: x | G19: 8.8 | H19: x | I19: 2.25 | J19: = | K19: =IF(C19,C19*E19*G19*I19,"") -> 168.3 | L19: Cum
B20: Piers | C20: 1 | D20: x | E20: 5.9 | F20: x | G20: 13.1 | H20: x | I20: 3 | J20: = | K20: =IF(C20,C20*E20*G20*I20,"") -> 231.87 | L20: Cum
C21: 1 | D21: x | E21: 5.9 | F21: x | G21: 13.1 | H21: x | I21: 3.15 | J21: = | K21: =IF(C21,C21*E21*G21*I21,"") -> 243.4635 | L21: Cum
C22: 1 | D22: x | E22: 5.9 | F22: x | G22: 13.1 | H22: x | I22: 2.85 | J22: = | K22: =IF(C22,C22*E22*G22*I22,"") -> 220.2765 | L22: Cum
B23: Abutment A2 | C23: 1 | D23: x | E23: 8.5 | F23: x | G23: 8.8 | H23: x | I23: 3 | J23: = | K23: =IF(C23,C23*E23*G23*I23,"") -> 224.4 | L23: Cum
G24: Total Qty. | K24: =SUM(K19:K23) -> 1088.31 | L24: Cum
A25: 4 | B25: Structural cement concrete (Design Mix) in open foundations, with form work, at level. Cement concrete for plain/reinforced concrete in open foundations as per drawing and technical specification. [MORTH Specification: Section 1700 & 1500). With 20mm nominal size aggregate P.C.C. M-20 grade
B26: Abutment A1 | C26: 1 | D26: x | E26: 8.5 | F26: x | G26: 8.8 | H26: x | I26: 0.3 | J26: = | K26: =IF(C26,C26*E26*G26*I26,"") -> 22.44 | L26: Cum
B27: Piers | C27: 1 | D27: x | E27: 5.9 | F27: x | G27: 13.1 | H27: x | I27: 0.3 | J27: = | K27: =IF(C27,C27*E27*G27*I27,"") -> 23.187 | L27: Cum
C28: 1 | D28: x | E28: 5.9 | F28: x | G28: 13.1 | H28: x | I28: 0.3 | J28: = | K28: =IF(C28,C28*E28*G28*I28,"") -> 23.187 | L28: Cum
C29: 1 | D29: x | E29: 5.9 | F29: x | G29: 13.1 | H29: x | I29: 0.3 | J29: = | K29: =IF(C29,C29*E29*G29*I29,"") -> 23.187 | L29: Cum
B30: Abutment A2 | C30: 1 | D30: x | E30: 8.5 | F30: x | G30: 8.8 | H30: x | I30: 0.3 | J30: = | K30: =IF(C30,C30*E30*G30*I30,"") -> 22.44 | L30: Cum
G31: Total Qty. | K31: =SUM(K26:K30) -> 114.441 | L31: Cum
A32: 5 | B32: Structural cement concrete (Design Mix) B-2 in open foundations, with form work, at 6.6.6 any level. Cement plain/reinforced concrete for concrete in open foundations as per drawing and technical specification. [MORTH Specification : Section 1700 & 1500]. With 20mm nominal size aggregate R.C.C. M-25 grade
B33: Abutment A1 | C33: 1 | D33: x | E33: 8.2 | F33: x | G33: 8.5 | H33: x | I33: 0.85 | J33: = | K33: =IF(C33,C33*E33*G33*I33,"") -> 59.245 | L33: Cum
C34: 1 | D34: x | E34: 4.75 | F34: x | G34: 8.5 | H34: x | I34: 1.8 | J34: = | K34: =IF(C34,C34*E34*G34*I34,"") -> 72.675 | L34: Cum
B35: Piers | C35: 1 | D35: x | E35: 5.6 | F35: x | G35: 12.8 | H35: x | I35: 3.1 | J35: = | K35: =IF(C35,C35*E35*G35*I35,"") -> 222.208 | L35: Cum
C36: 1 | D36: x | E36: 5.6 | F36: x | G36: 12.8 | H36: x | I36: 3.25 | J36: = | K36: =IF(C36,C36*E36*G36*I36,"") -> 232.96 | L36: Cum
C37: 1 | D37: x | E37: 5.6 | F37: x | G37: 12.8 | H37: x | I37: 3.3 | J37: = | K37: =IF(C37,C37*E37*G37*I37,"") -> 236.544 | L37: Cum
B38: Abutment A2 | C38: 1 | D38: x | E38: 8.2 | F38: x | G38: 8.5 | H38: x | I38: 0.85 | J38: = | K38: =IF(C38,C38*E38*G38*I38,"") -> 59.245 | L38: Cum
C39: 1 | D39: x | E39: 4.75 | F39: x | G39: 8.5 | H39: x | I39: 1.95 | J39: = | K39: =IF(C39,C39*E39*G39*I39,"") -> 78.73125 | L39: Cum
G40: Total Qty. | K40: =SUM(K33:K39) -> 961.60825 | L40: Cum
...
